#VRML_SIM R2021a utf8
WorldInfo {
  ERP 0.8
  basicTimeStep 8
  coordinateSystem "NUE"
}
Viewpoint {
  orientation 0.50336542268722 -0.7177481650612763 -0.4811037547079502 4.536564943931951
  position 2.2111143711378496 3.8098035179650913 0.09606339430108257
}
TexturedBackground {
}
TexturedBackgroundLight {
}
Floor {
  size 4 5
}
DEF PAUL Robot {
  translation 0.765864 0.41 -0.409223
  children [
    HingeJoint {
      jointParameters HingeJointParameters {
      }
      device [
        RotationalMotor {
        }
      ]
      endPoint Solid {
        translation 7.786619999999996e-26 1.3552527156068805e-20 0.12999999999999995
        rotation 1.47579197724711e-17 4.94486143025655e-18 1 1.5708003061003868
        children [
          DEF Wheel Shape {
            appearance PBRAppearance {
              baseColor 1 1 0
              metalness 0
            }
            geometry Cylinder {
              height 0.05
              radius 0.05
            }
          }
        ]
        name "solid(1)"
        boundingObject USE Wheel
        physics DEF Wheel_Physics Physics {
        }
      }
    }
    HingeJoint {
      jointParameters HingeJointParameters {
      }
      device [
        RotationalMotor {
        }
      ]
      endPoint Solid {
        translation 0.0999999999999999 -3.5138399999999826e-06 0.2847389999999998
        rotation -0.6546505699508647 -0.6546587754399333 0.37796100195985155 2.418855957070486
        children [
          USE Wheel
        ]
        name "solid(2)"
        boundingObject USE Wheel
        physics USE Wheel_Physics
      }
    }
    HingeJoint {
      jointParameters HingeJointParameters {
      }
      device [
        RotationalMotor {
        }
      ]
      endPoint Solid {
        translation -0.0918648 -4.65959e-06 0.281699
        rotation -0.4472080700149009 -0.4472200700167797 0.7745961212707783 1.8234699999999993
        children [
          USE Wheel
        ]
        name "solid(3)"
        boundingObject USE Wheel
        physics USE Wheel_Physics
      }
    }
    DEF Bounding_Box Solid {
      translation 0 0 -0.01
      children [
        DEF Body_Group Group {
          children [
            DEF Wheel_3_Transform Transform {
              translation -0.15072 0 0.32536
              rotation 0 -1 0 1.0472
              children [
                DEF Wheel_1_Mount Shape {
                  appearance PBRAppearance {
                  }
                  geometry Box {
                    size 0.05 0.1 0.05
                  }
                }
              ]
            }
            DEF Wheel_2_Transform Transform {
              translation 0.15938 0 0.33036
              rotation 0 1 0 -2.094395307179586
              children [
                DEF Wheel_1_Mount Shape {
                  appearance PBRAppearance {
                  }
                  geometry Box {
                    size 0.05 0.1 0.05
                  }
                }
              ]
            }
            DEF Wheel_1_Transform Transform {
              translation 0 0 0.07
              children [
                DEF Wheel_1_Mount Shape {
                  appearance PBRAppearance {
                  }
                  geometry Box {
                    size 0.05 0.1 0.05
                  }
                }
              ]
            }
            DEF Backplate_3_transform Transform {
              translation -0.19134 0 0.395
              rotation 0 -1 0 1.0472
              children [
                DEF Backplate_3 Shape {
                  appearance PBRAppearance {
                  }
                  geometry Box {
                    size 0.8 0.1 0.1
                  }
                }
              ]
            }
            DEF Backplate_2_transform Transform {
              translation 0.2 0 0.4
              rotation 0 1 0 -2.094395307179586
              children [
                DEF Backplate_2 Shape {
                  appearance PBRAppearance {
                  }
                  geometry Box {
                    size 0.8 0.1 0.1
                  }
                }
              ]
            }
            DEF Backplate_1 Shape {
              appearance PBRAppearance {
              }
              geometry Box {
                size 0.8 0.1 0.1
              }
            }
          ]
        }
      ]
    }
  ]
  name "robot(2)"
  boundingObject USE Body_Group
  physics Physics {
  }
}
DEF Pole Solid {
  translation 0.457853 1 0.626811
  scale 1.17147 1.17147 1.17147
  children [
    DEF Pole Shape {
      appearance PBRAppearance {
        baseColor 0.8 0.5 0
      }
      geometry Cylinder {
        radius 0.05
      }
    }
  ]
}
