#VRML_SIM R2021a utf8
WorldInfo {
  ERP 0.8
  basicTimeStep 8
  coordinateSystem "NUE"
}
Viewpoint {
  orientation 0.5572899334202956 -0.6791292017306658 -0.47771482860077846 4.589391605338137
  position 1.715487147159288 5.34500933876564 1.2095260444932183
}
TexturedBackground {
}
TexturedBackgroundLight {
}
Floor {
  size 4 5
  appearance Parquetry {
    type "light strip"
  }
}
DEF PAUL Robot {
  translation 0.498648 2.22866 0.500418
  rotation -0.09750149712630346 0.9951085232749551 -0.01588977544420951 -0.2627264330917525
  children [
    HingeJoint {
      jointParameters HingeJointParameters {
        position -0.011534861722278578
      }
      device [
        RotationalMotor {
        }
      ]
      endPoint Solid {
        translation 7.786619999999821e-26 0.0014994987712362838 0.12999135164861783
        rotation -0.005767280020432846 0.005767302970247369 0.9999667377956206 1.5708335688579207
        children [
          DEF Wheel Shape {
            appearance PBRAppearance {
              baseColor 1 1 0
              metalness 0
            }
            geometry Cylinder {
              height 0.05
              radius 0.05
            }
          }
        ]
        name "solid(1)"
        boundingObject USE Wheel
        physics DEF Wheel_Physics Physics {
        }
      }
    }
    HingeJoint {
      jointParameters HingeJointParameters {
        position -0.0070666374611780824
      }
      device [
        RotationalMotor {
        }
      ]
      endPoint Solid {
        translation 0.10000000000000059 0.002008616784946904 0.28473191530272707
        rotation -0.6554103727168137 -0.6527499732568509 0.37994041078620155 2.4234848238569704
        children [
          USE Wheel
        ]
        name "solid(2)"
        boundingObject USE Wheel
        physics USE Wheel_Physics
      }
    }
    HingeJoint {
      jointParameters HingeJointParameters {
        position -0.007057208442851071
      }
      device [
        RotationalMotor {
        }
      ]
      endPoint Solid {
        translation -0.09186479999999884 0.0019833325853571867 0.28169201801713695
        rotation -0.4493884616258179 -0.44394063461004274 0.7752204354244111 1.826633741635328
        children [
          USE Wheel
        ]
        name "solid(3)"
        boundingObject USE Wheel
        physics USE Wheel_Physics
      }
    }
    DEF Bounding_Box Solid {
      translation 0 0 -0.01
      children [
        DEF Body_Group Group {
          children [
            DEF Wheel_3_Transform Transform {
              translation -0.15072 0 0.32536
              rotation 0 -1 0 1.0472
              children [
                DEF Wheel_1_Mount Shape {
                  appearance PBRAppearance {
                  }
                  geometry Box {
                    size 0.05 0.1 0.05
                  }
                }
              ]
            }
            DEF Wheel_2_Transform Transform {
              translation 0.15938 0 0.33036
              rotation 0 1 0 -2.094395307179586
              children [
                DEF Wheel_1_Mount Shape {
                  appearance PBRAppearance {
                  }
                  geometry Box {
                    size 0.05 0.1 0.05
                  }
                }
              ]
            }
            DEF Wheel_1_Transform Transform {
              translation 0 0 0.07
              children [
                DEF Wheel_1_Mount Shape {
                  appearance PBRAppearance {
                  }
                  geometry Box {
                    size 0.05 0.1 0.05
                  }
                }
              ]
            }
            DEF Backplate_3_transform Transform {
              translation -0.19134 0 0.395
              rotation 0 -1 0 1.0472
              children [
                DEF Backplate_3 Shape {
                  appearance PBRAppearance {
                  }
                  geometry Box {
                    size 0.8 0.1 0.1
                  }
                }
              ]
            }
            DEF Backplate_2_transform Transform {
              translation 0.2 0 0.4
              rotation 0 1 0 -2.094395307179586
              children [
                DEF Backplate_2 Shape {
                  appearance PBRAppearance {
                  }
                  geometry Box {
                    size 0.8 0.1 0.1
                  }
                }
              ]
            }
            DEF Backplate_1 Shape {
              appearance PBRAppearance {
              }
              geometry Box {
                size 0.8 0.1 0.1
              }
            }
          ]
        }
      ]
    }
  ]
  name "robot(2)"
  boundingObject USE Body_Group
  physics Physics {
  }
}
DEF Pole Solid {
  translation 0.457853 1 0.626811
  children [
    DEF Pole Shape {
      appearance PBRAppearance {
      }
      geometry Cylinder {
        radius 0.05
      }
    }
  ]
  boundingObject USE Pole
}
