#VRML_SIM R2021a utf8
WorldInfo {
  ERP 0.8
  coordinateSystem "NUE"
  contactProperties [
    ContactProperties {
      material1 "wheel"
      material2 "pole"
      coulombFriction [
        -1
      ]
    }
  ]
}
Viewpoint {
  orientation -0.6501075131429858 0.7212327161048377 0.23913090677509896 0.648996633350861
  position 0.25238765483289083 0.3404456349301275 0.3844724230493114
}
TexturedBackground {
}
TexturedBackgroundLight {
}
Floor {
  size 3 3
}
Solid {
  translation 0 1 0
  children [
    DEF POLE Group {
      children [
        Shape {
          appearance PBRAppearance {
            baseColor 0.652857 0.64683 0.657359
            metalness 0
          }
          geometry Cylinder {
            radius 0.03
          }
        }
        Transform {
          translation 0 1 0
          children [
            Shape {
              appearance PBRAppearance {
                baseColor 0.710491 0.703914 0.715419
                roughness 1
                metalness 0
              }
              geometry Box {
                size 0.5 0.001 0.5
              }
            }
          ]
        }
      ]
    }
  ]
  name "pole"
  contactMaterial "pole"
  boundingObject USE POLE
}
Robot {
  children [
    Solid {
      children [
        DEF BODY Group {
          children [
            Transform {
              translation 0 0.1 0.08
              children [
                DEF BODY_SIDE Shape {
                  appearance PBRAppearance {
                    baseColor 0.156847 0.408667 0.997314
                    roughness 1
                    metalness 0
                  }
                  geometry Box {
                    size 0.24 0.03 0.03
                  }
                }
              ]
            }
            Transform {
              translation -0.06928 0.1 -0.04
              rotation 0 1 0 1.0467
              children [
                USE BODY_SIDE
              ]
            }
            Transform {
              translation 0.06928 0.1 -0.04
              rotation 0 1 0 -1.0467
              children [
                USE BODY_SIDE
              ]
            }
            Transform {
              translation 0.0175 0.1 0.055
              children [
                DEF BODY_CONNECTOR Shape {
                  appearance PBRAppearance {
                    baseColor 1 0.815076 0
                    roughness 1
                    metalness 0
                  }
                  geometry Box {
                    size 0.015 0.03 0.02
                  }
                }
              ]
            }
            Transform {
              translation -0.0175 0.1 0.055
              children [
                USE BODY_CONNECTOR
              ]
            }
            Transform {
              translation -0.03888 0.1 -0.04266
              rotation 0 1 0 1.0476
              children [
                USE BODY_CONNECTOR
              ]
            }
            Transform {
              translation -0.0564 0.1 -0.0123
              rotation 0 1 0 1.0476
              children [
                USE BODY_CONNECTOR
              ]
            }
            Transform {
              translation 0.03888 0.1 -0.04266
              rotation 0 1 0 -1.0467
              children [
                USE BODY_CONNECTOR
              ]
            }
            Transform {
              translation 0.0564 0.1 -0.0123
              rotation 0 1 0 -1.0467
              children [
                USE BODY_CONNECTOR
              ]
            }
            Transform {
              translation 0 0.1 0.045
              rotation 0 0 1 1.5708
              children [
                DEF AXIS Shape {
                  appearance PBRAppearance {
                    baseColor 0.649729 0 1
                    roughness 1
                    metalness 0
                  }
                  geometry Cylinder {
                    height 0.05
                    radius 0.003
                  }
                }
              ]
            }
            Transform {
              translation -0.03897 0.1 -0.0225
              rotation -0.866019052628739 0 -0.5000110003630134 1.5707999999999998
              children [
                USE AXIS
              ]
            }
            Transform {
              translation 0.03897 0.1 -0.0225
              rotation 0.8660190526287391 0 -0.5000110003630134 1.5708
              children [
                USE AXIS
              ]
            }
          ]
        }
      ]
      boundingObject USE BODY
      physics Physics {
      }
    }
    HingeJoint {
      jointParameters HingeJointParameters {
        axis -1 0 0
        anchor 0 0.1 0.045
      }
      device [
        RotationalMotor {
          name "wheel1"
        }
      ]
      endPoint Solid {
        translation 0 0.1 0.045
        rotation 0 0 1 1.5707999999999998
        children [
          DEF WHEEL Shape {
            appearance PBRAppearance {
              baseColor 0.612421 1 0.627466
              roughness 1
              metalness 0
            }
            geometry Cylinder {
              height 0.02
              radius 0.016
            }
          }
        ]
        name "wheel_shape1"
        contactMaterial "wheel"
        boundingObject USE WHEEL
        physics DEF WHEEL_PH Physics {
        }
      }
    }
    HingeJoint {
      jointParameters HingeJointParameters {
        axis 0.5 0 0.866
        anchor 0.039 0.1 -0.0225
      }
      device [
        RotationalMotor {
          name "wheel2"
        }
      ]
      endPoint Solid {
        translation 0.039 0.1 -0.0225
        rotation 0.8660190526287391 0 -0.5000110003630135 1.5707999999999995
        children [
          USE WHEEL
        ]
        name "wheel_shape2"
        contactMaterial "wheel"
        boundingObject USE WHEEL
        physics USE WHEEL_PH
      }
    }
    HingeJoint {
      jointParameters HingeJointParameters {
        axis 0.5 0 -0.866
        anchor -0.039 0.1 -0.0225
      }
      device [
        RotationalMotor {
          name "wheel3"
        }
      ]
      endPoint Solid {
        translation -0.039 0.1 -0.022499999999999996
        rotation -0.8660190396281662 0 -0.500011022880005 1.5707999999999995
        children [
          USE WHEEL
        ]
        name "wheel_shape3"
        contactMaterial "wheel"
        boundingObject USE WHEEL
        physics USE WHEEL_PH
      }
    }
    DistanceSensor {
      translation 0 0.115 0.075
      rotation 0 0 1 1.5708
      children [
        DEF D_SENSOR Shape {
          appearance PBRAppearance {
            baseColor 1 0 0
            roughness 1
            metalness 0
          }
          geometry Box {
            size 0.01 0.01 0.01
          }
        }
      ]
      name "ds_top"
      boundingObject USE D_SENSOR
      physics Physics {
      }
    }
    DistanceSensor {
      translation 0 0.085 0.075
      rotation 0 0 1 -1.5708
      children [
        USE D_SENSOR
      ]
      name "ds_bottom"
      boundingObject USE D_SENSOR
      physics Physics {
      }
    }
  ]
  name "PAUL"
  boundingObject USE BODY
  physics Physics {
  }
  rotationStep 0.1
  controller "PAUL_demo1"
}
