#VRML_SIM R2021a utf8
WorldInfo {
  ERP 0.8
  coordinateSystem "NUE"
  contactProperties [
    ContactProperties {
      material1 "wheel"
      material2 "pole"
      coulombFriction [
        -1
      ]
    }
  ]
}
Viewpoint {
  orientation -0.054646615531759826 0.9936774215116415 0.09807614077287014 1.45948006473851
  position 5.12128469354127 1.7525190772632198 0.2888699147536316
}
TexturedBackground {
}
TexturedBackgroundLight {
}
Floor {
  size 20 20
}
Solid {
  translation 0 1.48 0
  children [
    DEF POLE Group {
      children [
        Shape {
          appearance PBRAppearance {
            baseColor 0.652857 0.64683 0.657359
            metalness 0
          }
          geometry Cylinder {
            height 3
            radius 0.03
          }
        }
        Transform {
          translation 0 1.5 0
          children [
            Shape {
              appearance PBRAppearance {
                baseColor 0.710491 0.703914 0.715419
                roughness 1
                metalness 0
              }
              geometry Box {
                size 0.5 0.001 0.5
              }
            }
          ]
        }
      ]
    }
  ]
  name "pole"
  contactMaterial "pole"
  boundingObject USE POLE
}
Robot {
  translation -2.43925e-06 0.257774 1.47248e-05
  rotation -0.0016185199777112452 0.9999986004543824 -0.00042365358266536015 0.16330852631395845
  children [
    Solid {
      children [
        DEF BODY Group {
          children [
            DEF MOTOR_DISPLAY_1 Transform {
              translation -0.086827 0.111023 -0.0296244
              rotation -0.44706108459536525 0.44706208459555447 -0.7747721466066607 1.82325
              children [
                DEF MOTOR_MOCK Shape {
                  appearance PBRAppearance {
                    baseColor 1 0.7 0
                    metalness 0
                  }
                  geometry Cylinder {
                    height 0.02
                    radius 0.008
                  }
                }
              ]
            }
            DEF MOTOR_DISPLAY_2 Transform {
              translation 0.067929 0.11 -0.0623199
              rotation -0.4470590447982244 -0.4470590447982244 0.7747750776375028 1.82325
              children [
                USE MOTOR_MOCK
              ]
            }
            DEF MOTOR_DISPLAY_3 Transform {
              translation 0.02 0.11 0.09
              rotation 0 0 1 -1.5707953071795862
              children [
                USE MOTOR_MOCK
              ]
            }
            DEF PI_BOARD_BAY Transform {
              translation -0.0565695 0.1 -0.101955
              rotation 0 1 0 1.0467
              children [
                DEF PI_BAY Shape {
                  appearance PBRAppearance {
                    baseColor 0.3 0.7 0.3
                    roughness 1
                    metalness 0
                  }
                  geometry Box {
                    size 0.0856 0.011 0.026
                  }
                }
              ]
            }
            DEF MOTOR_BAY_1 Transform {
              translation 0.0529161 0.1 -0.0882933
              rotation 0 1 0 -1.0467
              children [
                DEF MOTOR_BAY Shape {
                  appearance PBRAppearance {
                    baseColor 0.8 0.8 0.9
                    roughness 1
                    metalness 0
                  }
                  geometry Box {
                    size 0.105 0.011 0.034
                  }
                }
              ]
            }
            DEF MOTOR_BAY_2 Transform {
              translation 0.05 0.1 0.09
              children [
                USE MOTOR_BAY
              ]
            }
            DEF MOTOR_BAY_3 Transform {
              translation -0.102959 0.1 -0.00171543
              rotation 0 1 0 1.0467
              children [
                USE MOTOR_BAY
              ]
            }
            DEF SMALL_JOINT_3 Transform {
              translation -0.12985 0.1 0.0750989
              rotation 0 1 0 -1.0467
              children [
                DEF SMALL_BODY_SIDE Shape {
                  appearance PBRAppearance {
                    baseColor 0.2 0.2 0.3
                    metalness 0
                  }
                  geometry Box {
                    size 0.1 0.03 0.01
                  }
                }
              ]
            }
            DEF SMALL_JOINT_2 Transform {
              translation 0.12985 0.1 0.075099
              rotation 0 1 0 1.0467
              children [
                USE SMALL_BODY_SIDE
              ]
            }
            DEF BACK_PLATE_1 Transform {
              translation 0 0.1 0.11
              children [
                DEF BODY_SIDE Shape {
                  appearance PBRAppearance {
                    baseColor 0.2 0.2 0.3
                    roughness 1
                    metalness 0
                  }
                  geometry Box {
                    size 0.221 0.03 0.01
                  }
                }
              ]
            }
            DEF SMALL_JOINT_1 Transform {
              translation 0 0.1 -0.15
              children [
                USE SMALL_BODY_SIDE
              ]
            }
            DEF BACK_PLATE_2 Transform {
              translation -0.0952532 0.1 -0.0550129
              rotation 0 1 0 1.0467
              children [
                DEF TEST Shape {
                  appearance PBRAppearance {
                    baseColor 0.2 0.2 0.3
                    roughness 1
                    metalness 0
                  }
                  geometry Box {
                    size 0.221 0.03 0.01
                  }
                }
              ]
            }
            DEF BACK_PLATE_3 Transform {
              translation 0.0952532 0.1 -0.0550129
              rotation 0 1 0 -1.0467
              children [
                Shape {
                  appearance PBRAppearance {
                    baseColor 0.2 0.2 0.3
                    roughness 1
                    metalness 0
                  }
                  geometry Box {
                    size 0.221 0.03 0.01
                  }
                }
              ]
            }
            Transform {
              translation 0.0175 0.1 0.055
              children [
                DEF BODY_CONNECTOR_SHORT Shape {
                  appearance PBRAppearance {
                    baseColor 0.2 0.2 0.3
                    roughness 1
                    metalness 0
                  }
                  geometry Box {
                    size 0.005 0.01 0.04
                  }
                }
              ]
            }
            Transform {
              translation -0.0175 0.1 0.075
              children [
                DEF BODY_CONNECTOR_LONG Shape {
                  appearance PBRAppearance {
                    baseColor 0.2 0.2 0.3
                    roughness 1
                    metalness 0
                  }
                  geometry Box {
                    size 0.005 0.01 0.079
                  }
                }
              ]
            }
            Transform {
              translation -0.0562046 0.1 -0.052653
              rotation 0 1 0 1.0476
              children [
                USE BODY_CONNECTOR_LONG
              ]
            }
            Transform {
              translation -0.0564 0.1 -0.0123
              rotation 0 1 0 1.0476
              children [
                USE BODY_CONNECTOR_SHORT
              ]
            }
            Transform {
              translation 0.03888 0.1 -0.04266
              rotation 0 1 0 -1.0467
              children [
                USE BODY_CONNECTOR_SHORT
              ]
            }
            Transform {
              translation 0.0737156 0.1 -0.0223086
              rotation 0 1 0 -1.0467
              children [
                USE BODY_CONNECTOR_LONG
              ]
            }
            Transform {
              translation 0 0.1 0.045
              rotation 0 0 1 1.5708
              children [
                DEF AXIS Shape {
                  appearance PBRAppearance {
                    baseColor 0.2 0.2 0.3
                    roughness 1
                    metalness 0
                  }
                  geometry Cylinder {
                    height 0.039
                    radius 0.003
                  }
                }
              ]
            }
            Transform {
              translation -0.03897 0.1 -0.0225
              rotation -0.866019052628739 0 -0.5000110003630134 1.5707999999999998
              children [
                USE AXIS
              ]
            }
            Transform {
              translation 0.03897 0.1 -0.0225
              rotation 0.8660190526287391 0 -0.5000110003630134 1.5708
              children [
                USE AXIS
              ]
            }
          ]
        }
        Group {
          children [
            DEF UV_Chasis SolidPipe {
              translation 0 0.12 0
              name "UV module(2)"
              height 0.001
              radius 0.05
              thickness 0.015
              appearance PBRAppearance {
                roughness 1
                metalness 0
              }
              physics Physics {
              }
            }
            DEF UV_Chasis SolidPipe {
              translation 0 0.14 0
              name "UV module(1)"
              height 0.001
              radius 0.05
              thickness 0.015
              appearance PBRAppearance {
                roughness 1
                metalness 0
              }
              physics Physics {
              }
            }
            SolidPipe {
              translation 0 0.13 0
              name "UV module"
              height 0.02
              radius 0.05
              thickness 0.005
              appearance PBRAppearance {
                roughness 1
                metalness 0
              }
              physics Physics {
              }
            }
            Solid {
              translation 0.088 0.12 0.05
              rotation 0.7255771900217981 -0.5459391429762939 -0.4189131097093782 -1.6267153071795866
              children [
                DEF UV_CONNECTOR Shape {
                  appearance PBRAppearance {
                    roughness 1
                    metalness 0
                  }
                  geometry Cylinder {
                    height 0.11
                    radius 0.004
                  }
                }
              ]
            }
            Transform {
              translation 0 0.12 -0.099
              rotation 1 0 0 1.309
              children [
                USE UV_CONNECTOR
              ]
            }
            Transform {
              translation -0.087 0.12 0.05
              rotation 0.7255801029453123 0.5459360774574161 0.41891205943524723 -1.626705307179586
              children [
                USE UV_CONNECTOR
              ]
            }
          ]
        }
      ]
      boundingObject USE BODY
      physics Physics {
      }
    }
    LED {
      translation 0 0.13 0
      children [
        SolidPipe {
          name "leds"
          height 0.01
          radius 0.045
          thickness 0.003
          appearance PBRAppearance {
            baseColor 0.7 0.7 0.7
            roughness 0.3
            metalness 0
            emissiveIntensity 6
          }
        }
      ]
      name "uv_led"
      color [
        0.5 0 1
      ]
      gradual TRUE
    }
    HingeJoint {
      jointParameters HingeJointParameters {
        position 86.55962482821381
        axis -1 0 0
        anchor 0 0.1 0.045
      }
      device [
        RotationalMotor {
          name "wheel1"
        }
      ]
      endPoint Solid {
        translation -4.3942327513355785e-08 0.10000030806636256 0.04500023546232452
        rotation 0.5728690697671018 -0.5728709677697938 0.5862080545255883 2.081162479856966
        children [
          DEF WHEEL_CENTRE Shape {
            appearance PBRAppearance {
              metalness 0
            }
            geometry Cylinder {
              height 0.021
              radius 0.012
            }
          }
          DEF WHEEL Shape {
            appearance PBRAppearance {
              baseColor 0 0 0
              roughness 1
              metalness 0
            }
            geometry Cylinder {
              height 0.02
              radius 0.016
            }
          }
        ]
        name "wheel_shape1"
        contactMaterial "wheel"
        boundingObject USE WHEEL
        physics DEF WHEEL_PH Physics {
        }
      }
    }
    HingeJoint {
      jointParameters HingeJointParameters {
        position 86.55931456649873
        axis 0.5 0 0.866
        anchor 0.039 0.1 -0.0225
      }
      device [
        RotationalMotor {
          name "wheel2"
        }
      ]
      endPoint Solid {
        translation 0.0390005958951954 0.10000034473106384 -0.022500450818578117
        rotation 0.22109582927350913 -0.5729303177057969 -0.7892195419092167 2.0813404527863892
        children [
          USE WHEEL_CENTRE
          USE WHEEL
        ]
        name "wheel_shape2"
        contactMaterial "wheel"
        boundingObject USE WHEEL
        physics USE WHEEL_PH
      }
    }
    HingeJoint {
      jointParameters HingeJointParameters {
        position 86.55976137094707
        axis 0.5 0 -0.866
        anchor -0.039 0.1 -0.0225
      }
      device [
        RotationalMotor {
          name "wheel3"
        }
      ]
      endPoint Solid {
        translation -0.03900061018320179 0.1000004181183618 -0.02250041667021129
        rotation -0.7941401607718647 -0.572844435405633 0.20295481732158657 2.0810794522337313
        children [
          USE WHEEL_CENTRE
          USE WHEEL
        ]
        name "wheel_shape3"
        contactMaterial "wheel"
        boundingObject USE WHEEL
        physics USE WHEEL_PH
      }
    }
    DistanceSensor {
      translation 0 0.115 0.11
      rotation 0 0 1 1.5708
      children [
        DEF D_SENSOR Shape {
          appearance PBRAppearance {
            baseColor 1 0 0
            roughness 1
            metalness 0
          }
          geometry Box {
            size 0.005 0.01 0.005
          }
        }
      ]
      name "ds_top"
      boundingObject USE D_SENSOR
      physics Physics {
      }
    }
    DistanceSensor {
      translation 0 0.085 0.105
      rotation 0 0 1 -1.5708
      children [
        USE D_SENSOR
      ]
      name "ds_bottom"
      boundingObject USE D_SENSOR
      physics Physics {
      }
    }
  ]
  name "PAUL"
  boundingObject USE BODY
  physics Physics {
  }
  rotationStep 0.1
  controller "paul_controller"
}
Solid {
  translation 0 1.52 5.22
  children [
    Solid {
      translation -4.89 -0.35 -3.85
      rotation 0 1 0 -1.5707953071795862
      children [
        Shape {
          appearance PBRAppearance {
            metalness 0
          }
          geometry Box {
            size 1.7 2.2 0.3
          }
        }
      ]
      name "solid(4)"
      boundingObject Box {
        size 0.1 0.1 0.1
      }
    }
    Solid {
      translation -4.89 -0.35 -6.54
      rotation 0 1 0 -1.5707953071795862
      children [
        Shape {
          appearance PBRAppearance {
            metalness 0
          }
          geometry Box {
            size 1.7 2.2 0.3
          }
        }
      ]
      name "solid(3)"
      boundingObject Box {
        size 0.1 0.1 0.1
      }
    }
    Solid {
      translation -4.89 1.04 -5.21
      rotation 0 1 0 -1.5707953071795862
      children [
        Shape {
          appearance PBRAppearance {
            metalness 0
          }
          geometry Box {
            size 4.5 0.9 0.3
          }
        }
      ]
      name "solid(2)"
      boundingObject Box {
        size 0.1 0.1 0.1
      }
    }
    Door {
      translation -4.9 -1.41 -5.19
      rotation 0 -0.9999999999999999 0 1.5707953071795862
      size 1 2 0.2
      doorAppearance GenericDoorAppearance {
        colorOverride 0.666667 0.333333 0
      }
    }
    Solid {
      translation 5.06 -0.02 -5.22
      rotation 0 1 0 -1.5707953071795862
      children [
        Shape {
          appearance PBRAppearance {
            metalness 0
          }
          geometry Box {
            size 4.5 3.3 0.3
          }
        }
      ]
      name "solid(1)"
      boundingObject Box {
        size 0.1 0.1 0.1
      }
    }
    Table {
      translation -0.41 -1.4 -6.55
      name "table(5)"
      size 1 0.67 1
    }
    Table {
      translation -3.42 -1.4 -6.55
      name "table(4)"
      size 1 0.67 1
    }
    Table {
      translation -3.42 -1.4 -4.14
      name "table(3)"
      size 1 0.67 1
    }
    Table {
      translation -0.42 -1.4 -4.14
      name "table(2)"
      size 1 0.67 1
    }
    Table {
      translation 2.59 -1.4 -6.55
      name "table(1)"
      size 1 0.67 1
    }
    Table {
      translation 2.59 -1.4 -4.14
      size 1 0.67 1
    }
    Chair {
      translation 3.64 -1.41 -6.5
      rotation 0 1 0 3.14159
      name "chair(5)"
    }
    Chair {
      translation -2.37 -1.41 -6.5
      rotation 0 1 0 3.14159
      name "chair(4)"
    }
    Chair {
      translation 0.63 -1.41 -6.5
      rotation 0 1 0 3.14159
      name "chair(3)"
    }
    Chair {
      translation 0.63 -1.41 -4.1
      rotation 0 1 0 3.14159
      name "chair(2)"
    }
    Chair {
      translation -2.37 -1.41 -4.1
      rotation 0 1 0 3.14159
      name "chair(1)"
    }
    Chair {
      translation 3.64 -1.41 -4.1
      rotation 0 1 0 3.14159
    }
    Solid {
      translation 0 0 -0.89
      children [
        DEF ceiling Solid {
          translation -0.03 1.55 -4.29
          children [
            Shape {
              appearance PBRAppearance {
                metalness 0
              }
              geometry Box {
                size 10 0.17 4
              }
            }
          ]
          name "ceiling"
          boundingObject Box {
            size 0.1 0.1 0.1
          }
        }
        Window {
          translation 0 -0.96 -2.23
          size 2 1.7 0.1
          bottomWallHeight 0.1
          windowHeight 1.5
          windowSillSize 0 0.01
          frameAppearance VarnishedPine {
            colorOverride 0 0 0
          }
        }
        Solid {
          translation -0.03 -1.47 -4.29
          children [
            Shape {
              appearance PBRAppearance {
                metalness 0
              }
              geometry Box {
                size 10 0.1 4
              }
            }
          ]
          boundingObject Box {
            size 0.1 0.1 0.1
          }
        }
        Floor {
          translation 0 -1.41 -4.3
          size 10 4
          appearance Parquetry {
            type "light strip"
            colorOverride 0.666667 0.333333 0
          }
        }
        Solid {
          translation -1.51 -0.21 -2.23
          children [
            Shape {
              appearance PBRAppearance {
                metalness 0
              }
              geometry Box {
                size 1 1.9 0.3
              }
            }
          ]
          name "solid(5)"
          boundingObject Box {
            size 0.1 0.1 0.1
          }
        }
        Solid {
          translation 0 -1.22 -2.23
          children [
            Shape {
              appearance PBRAppearance {
                metalness 0
              }
              geometry Box {
                size 10 0.6 0.3
              }
            }
          ]
          name "solid6(2)"
          boundingObject Box {
            size 0.1 0.1 0.1
          }
        }
        Window {
          translation -3.01 -0.96 -2.23
          name "window(2)"
          size 2 1.7 0.1
          bottomWallHeight 0.1
          windowHeight 1.5
          windowSillSize 0 0.01
          frameAppearance VarnishedPine {
            colorOverride 0 0 0
          }
        }
        Solid {
          translation 0 -1.22 -2.23
          children [
            Shape {
              appearance PBRAppearance {
                metalness 0
              }
              geometry Box {
                size 10 0.6 0.3
              }
            }
          ]
          name "solid6"
          boundingObject Box {
            size 0.1 0.1 0.1
          }
        }
        Window {
          translation 3.01 -0.96 -2.23
          name "window(1)"
          size 2 1.7 0.1
          bottomWallHeight 0.1
          windowHeight 1.5
          windowSillSize 0 0.01
          frameAppearance VarnishedPine {
            colorOverride 0 0 0
          }
        }
        Solid {
          translation 1.5 -0.21 -2.23
          children [
            Shape {
              appearance PBRAppearance {
                metalness 0
              }
              geometry Box {
                size 1 1.9 0.3
              }
            }
          ]
          name "solid(2)"
          boundingObject Box {
            size 0.1 0.1 0.1
          }
        }
        Solid {
          translation 4.5 -0.21 -2.23
          children [
            Shape {
              appearance PBRAppearance {
                metalness 0
              }
              geometry Box {
                size 1 1.9 0.3
              }
            }
          ]
          name "solid(3)"
          boundingObject Box {
            size 0.1 0.1 0.1
          }
        }
        Solid {
          translation -4.52 -0.21 -2.23
          children [
            Shape {
              appearance PBRAppearance {
                metalness 0
              }
              geometry Box {
                size 1 1.9 0.3
              }
            }
          ]
          name "solid(1)"
          boundingObject Box {
            size 0.1 0.1 0.1
          }
        }
        Solid {
          translation -4.52 -0.21 -2.23
          children [
            Shape {
              appearance PBRAppearance {
                metalness 0
              }
              geometry Box {
                size 1 1.9 0.3
              }
            }
          ]
          name "solid(4)"
          boundingObject Box {
            size 0.1 0.1 0.1
          }
        }
        Solid {
          translation 0 1.18 -2.23
          children [
            Shape {
              appearance PBRAppearance {
                metalness 0
              }
              geometry Box {
                size 10 0.9 0.3
              }
            }
          ]
          name "solid6(1)"
          boundingObject Box {
            size 0.1 0.1 0.1
          }
        }
      ]
      name "solid(6)"
    }
    Solid {
      translation 0 0 -5.08
      children [
        Window {
          translation 0 -0.96 -2.23
          size 2 1.7 0.1
          bottomWallHeight 0.1
          windowHeight 1.5
          windowSillSize 0 0.01
          frameAppearance VarnishedPine {
            colorOverride 0 0 0
          }
        }
        Solid {
          translation -1.51 -0.21 -2.23
          children [
            Shape {
              appearance PBRAppearance {
                metalness 0
              }
              geometry Box {
                size 1 1.9 0.3
              }
            }
          ]
          name "solid(1)"
          boundingObject Box {
            size 0.1 0.1 0.1
          }
        }
        Solid {
          translation 0 -1.22 -2.23
          children [
            Shape {
              appearance PBRAppearance {
                metalness 0
              }
              geometry Box {
                size 10 0.6 0.3
              }
            }
          ]
          name "solid6"
          boundingObject Box {
            size 0.1 0.1 0.1
          }
        }
        Window {
          translation -3.01 -0.96 -2.23
          name "window(2)"
          size 2 1.7 0.1
          bottomWallHeight 0.1
          windowHeight 1.5
          windowSillSize 0 0.01
          frameAppearance VarnishedPine {
            colorOverride 0 0 0
          }
        }
        Window {
          translation 3.01 -0.96 -2.23
          name "window(1)"
          size 2 1.7 0.1
          bottomWallHeight 0.1
          windowHeight 1.5
          windowSillSize 0 0.01
          frameAppearance VarnishedPine {
            colorOverride 0 0 0
          }
        }
        Solid {
          translation 1.5 -0.21 -2.23
          children [
            Shape {
              appearance PBRAppearance {
                metalness 0
              }
              geometry Box {
                size 1 1.9 0.3
              }
            }
          ]
          name "solid(2)"
          boundingObject Box {
            size 0.1 0.1 0.1
          }
        }
        Solid {
          translation 4.5 -0.21 -2.23
          children [
            Shape {
              appearance PBRAppearance {
                metalness 0
              }
              geometry Box {
                size 1 1.9 0.3
              }
            }
          ]
          name "solid(3)"
          boundingObject Box {
            size 0.1 0.1 0.1
          }
        }
        Solid {
          translation -4.52 -0.21 -2.23
          children [
            Shape {
              appearance PBRAppearance {
                metalness 0
              }
              geometry Box {
                size 1 1.9 0.3
              }
            }
          ]
          name "solid(4)"
          boundingObject Box {
            size 0.1 0.1 0.1
          }
        }
        Solid {
          translation 0 1.18 -2.23
          children [
            Shape {
              appearance PBRAppearance {
                metalness 0
              }
              geometry Box {
                size 10 0.9 0.3
              }
            }
          ]
          name "solid6(2)"
          boundingObject Box {
            size 0.1 0.1 0.1
          }
        }
      ]
      name "solid(5)"
    }
  ]
}
