#VRML_SIM R2021a utf8
WorldInfo {
  ERP 0.8
  coordinateSystem "NUE"
  contactProperties [
    ContactProperties {
      material1 "wheel"
      material2 "pole"
      coulombFriction [
        -1
      ]
    }
  ]
}
Viewpoint {
  orientation -0.5082577724460264 0.7496953110669407 0.42382894817655686 1.5538133056844288
  position 1.2896310957907677 2.8447950755217413 0.4193203341030124
}
TexturedBackground {
}
TexturedBackgroundLight {
}
Floor {
  size 3 3
}
Solid {
  translation 0 1 0
  children [
    DEF POLE Group {
      children [
        Shape {
          appearance PBRAppearance {
            baseColor 0.652857 0.64683 0.657359
            metalness 0
          }
          geometry Cylinder {
            radius 0.03
          }
        }
        Transform {
          translation 0 1 0
          children [
            Shape {
              appearance PBRAppearance {
                baseColor 0.710491 0.703914 0.715419
                roughness 1
                metalness 0
              }
              geometry Box {
                size 0.5 0.001 0.5
              }
            }
          ]
        }
      ]
    }
  ]
  name "pole"
  contactMaterial "pole"
  boundingObject USE POLE
}
Robot {
  translation -0.0013297505814058985 1.143380824534249 0.0002251858296505758
  rotation -0.47182133236778384 -0.1490138025199921 0.8690106541241149 -0.013737227304102893
  children [
    Solid {
      children [
        DEF BODY Group {
          children [
            DEF MOTOR_DISPLAY_1 Transform {
              translation -0.086827 0.111023 -0.0296244
              rotation -0.44706108459536525 0.44706208459555447 -0.7747721466066607 1.82325
              children [
                DEF MOTOR_MOCK Shape {
                  appearance PBRAppearance {
                    baseColor 1 0.7 0
                    metalness 0
                  }
                  geometry Cylinder {
                    height 0.02
                    radius 0.008
                  }
                }
              ]
            }
            DEF MOTOR_DISPLAY_2 Transform {
              translation 0.067929 0.11 -0.0623199
              rotation -0.4470590447982244 -0.4470590447982244 0.7747750776375028 1.82325
              children [
                USE MOTOR_MOCK
              ]
            }
            DEF MOTOR_DISPLAY_3 Transform {
              translation 0.02 0.11 0.09
              rotation 0 0 1 -1.5707953071795862
              children [
                USE MOTOR_MOCK
              ]
            }
            DEF PI_BOARD_BAY Transform {
              translation -0.0565695 0.1 -0.101955
              rotation 0 1 0 1.0467
              children [
                DEF PI_BAY Shape {
                  appearance PBRAppearance {
                    baseColor 0.3 0.7 0.3
                    roughness 1
                    metalness 0
                  }
                  geometry Box {
                    size 0.0856 0.011 0.026
                  }
                }
              ]
            }
            DEF MOTOR_BAY_1 Transform {
              translation 0.0529161 0.1 -0.0882933
              rotation 0 1 0 -1.0467
              children [
                DEF MOTOR_BAY Shape {
                  appearance PBRAppearance {
                    baseColor 0.8 0.8 0.9
                    roughness 1
                    metalness 0
                  }
                  geometry Box {
                    size 0.105 0.011 0.034
                  }
                }
              ]
            }
            DEF MOTOR_BAY_2 Transform {
              translation 0.05 0.1 0.09
              children [
                USE MOTOR_BAY
              ]
            }
            DEF MOTOR_BAY_3 Transform {
              translation -0.102959 0.1 -0.00171543
              rotation 0 1 0 1.0467
              children [
                USE MOTOR_BAY
              ]
            }
            DEF SMALL_JOINT_3 Transform {
              translation -0.12985 0.1 0.0750989
              rotation 0 1 0 -1.0467
              children [
                DEF SMALL_BODY_SIDE Shape {
                  appearance PBRAppearance {
                    baseColor 0.2 0.2 0.3
                    metalness 0
                  }
                  geometry Box {
                    size 0.1 0.03 0.01
                  }
                }
              ]
            }
            DEF SMALL_JOINT_2 Transform {
              translation 0.12985 0.1 0.075099
              rotation 0 1 0 1.0467
              children [
                USE SMALL_BODY_SIDE
              ]
            }
            DEF BACK_PLATE_1 Transform {
              translation 0 0.1 0.11
              children [
                DEF BODY_SIDE Shape {
                  appearance PBRAppearance {
                    baseColor 0.2 0.2 0.3
                    roughness 1
                    metalness 0
                  }
                  geometry Box {
                    size 0.221 0.03 0.01
                  }
                }
              ]
            }
            DEF SMALL_JOINT_1 Transform {
              translation 0 0.1 -0.15
              children [
                USE SMALL_BODY_SIDE
              ]
            }
            DEF BACK_PLATE_2 Transform {
              translation -0.0952532 0.1 -0.0550129
              rotation 0 1 0 1.0467
              children [
                DEF TEST Shape {
                  appearance PBRAppearance {
                    baseColor 0.2 0.2 0.3
                    roughness 1
                    metalness 0
                  }
                  geometry Box {
                    size 0.221 0.03 0.01
                  }
                }
              ]
            }
            DEF BACK_PLATE_3 Transform {
              translation 0.0952532 0.1 -0.0550129
              rotation 0 1 0 -1.0467
              children [
                Shape {
                  appearance PBRAppearance {
                    baseColor 0.2 0.2 0.3
                    roughness 1
                    metalness 0
                  }
                  geometry Box {
                    size 0.221 0.03 0.01
                  }
                }
              ]
            }
            Transform {
              translation 0.0175 0.1 0.055
              children [
                DEF BODY_CONNECTOR_SHORT Shape {
                  appearance PBRAppearance {
                    baseColor 0.2 0.2 0.3
                    roughness 1
                    metalness 0
                  }
                  geometry Box {
                    size 0.005 0.01 0.04
                  }
                }
              ]
            }
            Transform {
              translation -0.0175 0.1 0.075
              children [
                DEF BODY_CONNECTOR_LONG Shape {
                  appearance PBRAppearance {
                    baseColor 0.2 0.2 0.3
                    roughness 1
                    metalness 0
                  }
                  geometry Box {
                    size 0.005 0.01 0.079
                  }
                }
              ]
            }
            Transform {
              translation -0.0562046 0.1 -0.052653
              rotation 0 1 0 1.0476
              children [
                USE BODY_CONNECTOR_LONG
              ]
            }
            Transform {
              translation -0.0564 0.1 -0.0123
              rotation 0 1 0 1.0476
              children [
                USE BODY_CONNECTOR_SHORT
              ]
            }
            Transform {
              translation 0.03888 0.1 -0.04266
              rotation 0 1 0 -1.0467
              children [
                USE BODY_CONNECTOR_SHORT
              ]
            }
            Transform {
              translation 0.0737156 0.1 -0.0223086
              rotation 0 1 0 -1.0467
              children [
                USE BODY_CONNECTOR_LONG
              ]
            }
            Transform {
              translation 0 0.1 0.045
              rotation 0 0 1 1.5708
              children [
                DEF AXIS Shape {
                  appearance PBRAppearance {
                    baseColor 0.2 0.2 0.3
                    roughness 1
                    metalness 0
                  }
                  geometry Cylinder {
                    height 0.039
                    radius 0.003
                  }
                }
              ]
            }
            Transform {
              translation -0.03897 0.1 -0.0225
              rotation -0.866019052628739 0 -0.5000110003630134 1.5707999999999998
              children [
                USE AXIS
              ]
            }
            Transform {
              translation 0.03897 0.1 -0.0225
              rotation 0.8660190526287391 0 -0.5000110003630134 1.5708
              children [
                USE AXIS
              ]
            }
          ]
        }
        Group {
          children [
            SolidPipe {
              translation 0 0.13 0
              name "UV module"
              height 0.02
              radius 0.05
              thickness 0.005
              appearance PBRAppearance {
                roughness 1
                metalness 0
              }
              physics Physics {
              }
            }
            Solid {
              translation 0.088 0.12 0.05
              rotation 0.7255771900217981 -0.5459391429762939 -0.4189131097093782 -1.6267153071795866
              children [
                DEF UV_CONNECTOR Shape {
                  appearance PBRAppearance {
                    roughness 1
                    metalness 0
                  }
                  geometry Cylinder {
                    height 0.11
                    radius 0.004
                  }
                }
              ]
            }
            Transform {
              translation 0 0.12 -0.099
              rotation 1 0 0 1.309
              children [
                USE UV_CONNECTOR
              ]
            }
            Transform {
              translation -0.087 0.12 0.05
              rotation 0.7255801029453123 0.5459360774574161 0.41891205943524723 -1.626705307179586
              children [
                USE UV_CONNECTOR
              ]
            }
          ]
        }
      ]
      boundingObject USE BODY
      physics Physics {
      }
    }
    LED {
      translation 0 0.13 0
      children [
        SolidPipe {
          name "leds"
          height 0.01
          radius 0.045
          thickness 0.003
          appearance PBRAppearance {
            baseColor 0.7 0.7 0.7
            roughness 0.3
            metalness 0
            emissiveColor 0.5 0 1
            emissiveIntensity 6
          }
        }
      ]
      name "uv_led"
      color [
        0.5 0 1
      ]
      gradual TRUE
    }
    HingeJoint {
      jointParameters HingeJointParameters {
        position 67.03987108499446
        axis -1 0 0
        anchor 0 0.1 0.045
      }
      device [
        RotationalMotor {
          name "wheel1"
        }
      ]
      endPoint Solid {
        translation -3.4923078019098415e-08 0.10000092645488887 0.04499794301707656
        rotation 0.6650035187432171 -0.6650055984372791 0.3399086261132777 2.4862814477689446
        children [
          DEF WHEEL_CENTRE Shape {
            appearance PBRAppearance {
              metalness 0
            }
            geometry Cylinder {
              height 0.021
              radius 0.012
            }
          }
          DEF WHEEL Shape {
            appearance PBRAppearance {
              baseColor 0 0 0
              roughness 1
              metalness 0
            }
            geometry Cylinder {
              height 0.02
              radius 0.016
            }
          }
        ]
        name "wheel_shape1"
        contactMaterial "wheel"
        boundingObject USE WHEEL
        physics DEF WHEEL_PH Physics {
        }
        linearVelocity 0.0009566688784306107 0.08050331525127118 0.0005291401855530474
        angularVelocity -5.04908349426398 0.059837413439317616 0.0005976592395606985
      }
    }
    HingeJoint {
      jointParameters HingeJointParameters {
        position 67.03980626430833
        axis 0.5 0 0.866
        anchor 0.039 0.1 -0.0225
      }
      device [
        RotationalMotor {
          name "wheel2"
        }
      ]
      endPoint Solid {
        translation 0.03899832619503108 0.10000030155906142 -0.02249911984043769
        rotation -0.03816356874417242 -0.665011406541364 -0.7458574737780573 2.486325778077407
        children [
          USE WHEEL_CENTRE
          USE WHEEL
        ]
        name "wheel_shape2"
        contactMaterial "wheel"
        boundingObject USE WHEEL
        physics USE WHEEL_PH
        linearVelocity 0.0008951400663821287 0.07678916350182953 0.0005046639902432249
        angularVelocity 2.4586217445606864 -0.060441562706072954 4.315416854582577
      }
    }
    HingeJoint {
      jointParameters HingeJointParameters {
        position 67.03974419098476
        axis 0.5 0 -0.866
        anchor -0.039 0.1 -0.0225
      }
      device [
        RotationalMotor {
          name "wheel3"
        }
      ]
      endPoint Solid {
        translation -0.03899816412546745 0.10000001565362723 -0.02249899865618475
        rotation -0.6268410942656351 -0.665018124292865 0.40598169527930794 2.486362727212492
        children [
          USE WHEEL_CENTRE
          USE WHEEL
        ]
        name "wheel_shape3"
        contactMaterial "wheel"
        boundingObject USE WHEEL
        physics USE WHEEL_PH
        linearVelocity 0.0009070447855511029 0.07754567586329471 0.0005187956661254597
        angularVelocity 2.4411664855200756 0.0031098802171656836 -4.345146267708152
      }
    }
    DistanceSensor {
      translation 0 0.115 0.11
      rotation 0 0 1 1.5708
      children [
        DEF D_SENSOR Shape {
          appearance PBRAppearance {
            baseColor 1 0 0
            roughness 1
            metalness 0
          }
          geometry Box {
            size 0.005 0.01 0.005
          }
        }
      ]
      name "ds_top"
      boundingObject USE D_SENSOR
      physics Physics {
      }
    }
    DistanceSensor {
      translation 0 0.085 0.105
      rotation 0 0 1 -1.5708
      children [
        USE D_SENSOR
      ]
      name "ds_bottom"
      boundingObject USE D_SENSOR
      physics Physics {
      }
    }
  ]
  name "PAUL"
  boundingObject USE BODY
  physics Physics {
  }
  rotationStep 0.1
  controller "paul_controller"
  linearVelocity 0.0009276609348433893 0.0780624558538012 0.0004605452431544683
  angularVelocity -0.04944242512342372 0.0008279774210757403 -0.009610676757197482
}
