#VRML_SIM R2021a utf8
WorldInfo {
  ERP 0.8
  coordinateSystem "NUE"
  contactProperties [
    ContactProperties {
      material1 "wheel"
      material2 "pole"
      coulombFriction [
        -1
      ]
    }
  ]
}
Viewpoint {
  orientation -0.10513943645418092 0.9296314537957672 0.3531728458073547 2.4590048278806016
  position 0.3339955114592027 0.6995804861265638 -0.43992406872694
}
TexturedBackground {
}
TexturedBackgroundLight {
}
Floor {
  size 3 3
}
Solid {
  translation 0 1 0
  children [
    DEF POLE Group {
      children [
        Shape {
          appearance PBRAppearance {
            baseColor 0.652857 0.64683 0.657359
            metalness 0
          }
          geometry Cylinder {
            radius 0.03
          }
        }
        Transform {
          translation 0 1 0
          children [
            Shape {
              appearance PBRAppearance {
                baseColor 0.710491 0.703914 0.715419
                roughness 1
                metalness 0
              }
              geometry Box {
                size 0.5 0.001 0.5
              }
            }
          ]
        }
      ]
    }
  ]
  name "pole"
  contactMaterial "pole"
  boundingObject USE POLE
}
Robot {
  translation -7.173650173230434e-06 0.15777403115844263 4.160279742575473e-05
  rotation -0.001618519977711245 0.9999986004543825 -0.0004236535826653602 0.1633085263139573
  children [
    Solid {
      children [
        DEF BODY Group {
          children [
            DEF MOTOR_DISPLAY_1 Transform {
              translation -0.086827 0.111023 -0.0296244
              rotation -0.44706108459536525 0.44706208459555447 -0.7747721466066607 1.82325
              children [
                DEF MOTOR_MOCK Shape {
                  appearance PBRAppearance {
                    baseColor 1 0.7 0
                    metalness 0
                  }
                  geometry Cylinder {
                    height 0.02
                    radius 0.008
                  }
                }
              ]
            }
            DEF MOTOR_DISPLAY_2 Transform {
              translation 0.067929 0.11 -0.0623199
              rotation -0.4470590447982244 -0.4470590447982244 0.7747750776375028 1.82325
              children [
                USE MOTOR_MOCK
              ]
            }
            DEF MOTOR_DISPLAY_3 Transform {
              translation 0.02 0.11 0.09
              rotation 0 0 1 -1.5707953071795862
              children [
                USE MOTOR_MOCK
              ]
            }
            DEF PI_BOARD_BAY Transform {
              translation -0.0565695 0.1 -0.101955
              rotation 0 1 0 1.0467
              children [
                DEF PI_BAY Shape {
                  appearance PBRAppearance {
                    baseColor 0.3 0.7 0.3
                    roughness 1
                    metalness 0
                  }
                  geometry Box {
                    size 0.0856 0.011 0.026
                  }
                }
              ]
            }
            DEF MOTOR_BAY_1 Transform {
              translation 0.0529161 0.1 -0.0882933
              rotation 0 1 0 -1.0467
              children [
                DEF MOTOR_BAY Shape {
                  appearance PBRAppearance {
                    baseColor 0.8 0.8 0.9
                    roughness 1
                    metalness 0
                  }
                  geometry Box {
                    size 0.105 0.011 0.034
                  }
                }
              ]
            }
            DEF MOTOR_BAY_2 Transform {
              translation 0.05 0.1 0.09
              children [
                USE MOTOR_BAY
              ]
            }
            DEF MOTOR_BAY_3 Transform {
              translation -0.102959 0.1 -0.00171543
              rotation 0 1 0 1.0467
              children [
                USE MOTOR_BAY
              ]
            }
            DEF SMALL_JOINT_3 Transform {
              translation -0.12985 0.1 0.0750989
              rotation 0 1 0 -1.0467
              children [
                DEF SMALL_BODY_SIDE Shape {
                  appearance PBRAppearance {
                    baseColor 0.2 0.2 0.3
                    metalness 0
                  }
                  geometry Box {
                    size 0.1 0.03 0.01
                  }
                }
              ]
            }
            DEF SMALL_JOINT_2 Transform {
              translation 0.12985 0.1 0.075099
              rotation 0 1 0 1.0467
              children [
                USE SMALL_BODY_SIDE
              ]
            }
            DEF BACK_PLATE_1 Transform {
              translation 0 0.1 0.11
              children [
                DEF BODY_SIDE Shape {
                  appearance PBRAppearance {
                    baseColor 0.2 0.2 0.3
                    roughness 1
                    metalness 0
                  }
                  geometry Box {
                    size 0.221 0.03 0.01
                  }
                }
              ]
            }
            DEF SMALL_JOINT_1 Transform {
              translation 0 0.1 -0.15
              children [
                USE SMALL_BODY_SIDE
              ]
            }
            DEF BACK_PLATE_2 Transform {
              translation -0.0952532 0.1 -0.0550129
              rotation 0 1 0 1.0467
              children [
                DEF TEST Shape {
                  appearance PBRAppearance {
                    baseColor 0.2 0.2 0.3
                    roughness 1
                    metalness 0
                  }
                  geometry Box {
                    size 0.221 0.03 0.01
                  }
                }
              ]
            }
            DEF BACK_PLATE_3 Transform {
              translation 0.0952532 0.1 -0.0550129
              rotation 0 1 0 -1.0467
              children [
                Shape {
                  appearance PBRAppearance {
                    baseColor 0.2 0.2 0.3
                    roughness 1
                    metalness 0
                  }
                  geometry Box {
                    size 0.221 0.03 0.01
                  }
                }
              ]
            }
            Transform {
              translation 0.0175 0.1 0.055
              children [
                DEF BODY_CONNECTOR_SHORT Shape {
                  appearance PBRAppearance {
                    baseColor 0.2 0.2 0.3
                    roughness 1
                    metalness 0
                  }
                  geometry Box {
                    size 0.005 0.01 0.04
                  }
                }
              ]
            }
            Transform {
              translation -0.0175 0.1 0.075
              children [
                DEF BODY_CONNECTOR_LONG Shape {
                  appearance PBRAppearance {
                    baseColor 0.2 0.2 0.3
                    roughness 1
                    metalness 0
                  }
                  geometry Box {
                    size 0.005 0.01 0.079
                  }
                }
              ]
            }
            Transform {
              translation -0.0562046 0.1 -0.052653
              rotation 0 1 0 1.0476
              children [
                USE BODY_CONNECTOR_LONG
              ]
            }
            Transform {
              translation -0.0564 0.1 -0.0123
              rotation 0 1 0 1.0476
              children [
                USE BODY_CONNECTOR_SHORT
              ]
            }
            Transform {
              translation 0.03888 0.1 -0.04266
              rotation 0 1 0 -1.0467
              children [
                USE BODY_CONNECTOR_SHORT
              ]
            }
            Transform {
              translation 0.0737156 0.1 -0.0223086
              rotation 0 1 0 -1.0467
              children [
                USE BODY_CONNECTOR_LONG
              ]
            }
            Transform {
              translation 0 0.1 0.045
              rotation 0 0 1 1.5708
              children [
                DEF AXIS Shape {
                  appearance PBRAppearance {
                    baseColor 0.2 0.2 0.3
                    roughness 1
                    metalness 0
                  }
                  geometry Cylinder {
                    height 0.039
                    radius 0.003
                  }
                }
              ]
            }
            Transform {
              translation -0.03897 0.1 -0.0225
              rotation -0.866019052628739 0 -0.5000110003630134 1.5707999999999998
              children [
                USE AXIS
              ]
            }
            Transform {
              translation 0.03897 0.1 -0.0225
              rotation 0.8660190526287391 0 -0.5000110003630134 1.5708
              children [
                USE AXIS
              ]
            }
          ]
        }
        Group {
          children [
            DEF UV_Chasis SolidPipe {
              translation 0 0.12 0
              name "UV module(2)"
              height 0.001
              radius 0.05
              thickness 0.015
              appearance PBRAppearance {
                roughness 1
                metalness 0
              }
              physics Physics {
              }
            }
            DEF UV_Chasis SolidPipe {
              translation 0 0.14 0
              name "UV module(1)"
              height 0.001
              radius 0.05
              thickness 0.015
              appearance PBRAppearance {
                roughness 1
                metalness 0
              }
              physics Physics {
              }
            }
            SolidPipe {
              translation 0 0.13 0
              name "UV module"
              height 0.02
              radius 0.05
              thickness 0.005
              appearance PBRAppearance {
                roughness 1
                metalness 0
              }
              physics Physics {
              }
            }
            Solid {
              translation 0.088 0.12 0.05
              rotation 0.7255771900217981 -0.5459391429762939 -0.4189131097093782 -1.6267153071795866
              children [
                DEF UV_CONNECTOR Shape {
                  appearance PBRAppearance {
                    roughness 1
                    metalness 0
                  }
                  geometry Cylinder {
                    height 0.11
                    radius 0.004
                  }
                }
              ]
            }
            Transform {
              translation 0 0.12 -0.099
              rotation 1 0 0 1.309
              children [
                USE UV_CONNECTOR
              ]
            }
            Transform {
              translation -0.087 0.12 0.05
              rotation 0.7255801029453123 0.5459360774574161 0.41891205943524723 -1.626705307179586
              children [
                USE UV_CONNECTOR
              ]
            }
          ]
        }
      ]
      boundingObject USE BODY
      physics Physics {
      }
    }
    LED {
      translation 0 0.13 0
      children [
        SolidPipe {
          name "leds"
          height 0.01
          radius 0.045
          thickness 0.003
          appearance PBRAppearance {
            baseColor 0.7 0.7 0.7
            roughness 0.3
            metalness 0
            emissiveColor 0.5 0 1
            emissiveIntensity 6
          }
        }
      ]
      name "uv_led"
      color [
        0.5 0 1
      ]
      gradual TRUE
    }
    HingeJoint {
      jointParameters HingeJointParameters {
        position 86.55962482821381
        axis -1 0 0
        anchor 0 0.1 0.045
      }
      device [
        RotationalMotor {
          name "wheel1"
        }
      ]
      endPoint Solid {
        translation -4.3942327513355785e-08 0.10000030806636256 0.04500023546232452
        rotation 0.5728690697671018 -0.572870967769794 0.5862080545255884 2.081162479856966
        children [
          DEF WHEEL_CENTRE Shape {
            appearance PBRAppearance {
              metalness 0
            }
            geometry Cylinder {
              height 0.021
              radius 0.012
            }
          }
          DEF WHEEL Shape {
            appearance PBRAppearance {
              baseColor 0 0 0
              roughness 1
              metalness 0
            }
            geometry Cylinder {
              height 0.02
              radius 0.016
            }
          }
        ]
        name "wheel_shape1"
        contactMaterial "wheel"
        boundingObject USE WHEEL
        physics DEF WHEEL_PH Physics {
        }
      }
    }
    HingeJoint {
      jointParameters HingeJointParameters {
        position 86.55931456649873
        axis 0.5 0 0.866
        anchor 0.039 0.1 -0.0225
      }
      device [
        RotationalMotor {
          name "wheel2"
        }
      ]
      endPoint Solid {
        translation 0.0390005958951954 0.10000034473106384 -0.02250045081857811
        rotation 0.22109582927350907 -0.5729303177057969 -0.7892195419092167 2.0813404527863892
        children [
          USE WHEEL_CENTRE
          USE WHEEL
        ]
        name "wheel_shape2"
        contactMaterial "wheel"
        boundingObject USE WHEEL
        physics USE WHEEL_PH
      }
    }
    HingeJoint {
      jointParameters HingeJointParameters {
        position 86.55976137094707
        axis 0.5 0 -0.866
        anchor -0.039 0.1 -0.0225
      }
      device [
        RotationalMotor {
          name "wheel3"
        }
      ]
      endPoint Solid {
        translation -0.0390006101832018 0.1000004181183618 -0.022500416670211288
        rotation -0.7941401607718647 -0.5728444354056329 0.20295481732158677 2.081079452233731
        children [
          USE WHEEL_CENTRE
          USE WHEEL
        ]
        name "wheel_shape3"
        contactMaterial "wheel"
        boundingObject USE WHEEL
        physics USE WHEEL_PH
      }
    }
    DistanceSensor {
      translation 0 0.115 0.11
      rotation 0 0 1 1.5708
      children [
        DEF D_SENSOR Shape {
          appearance PBRAppearance {
            baseColor 1 0 0
            roughness 1
            metalness 0
          }
          geometry Box {
            size 0.005 0.01 0.005
          }
        }
      ]
      name "ds_top"
      boundingObject USE D_SENSOR
      physics Physics {
      }
    }
    DistanceSensor {
      translation 0 0.085 0.105
      rotation 0 0 1 -1.5708
      children [
        USE D_SENSOR
      ]
      name "ds_bottom"
      boundingObject USE D_SENSOR
      physics Physics {
      }
    }
  ]
  name "PAUL"
  boundingObject USE BODY
  physics Physics {
  }
  rotationStep 0.1
  controller "paul_controller"
  linearVelocity 4.02025983450728e-06 0.07826630266476683 -2.0686071450256456e-05
  angularVelocity -0.00030611203195545525 -1.096691641979084e-06 -3.7077069004849135e-05
}
