#VRML_SIM R2021a utf8
WorldInfo {
  ERP 0.8
  coordinateSystem "NUE"
  contactProperties [
    ContactProperties {
      material1 "wheel"
      material2 "pole"
      coulombFriction [
        -1
      ]
    }
  ]
}
Viewpoint {
  orientation -0.3756786240162024 0.8784288592461639 0.29534439337962 1.2728535241336665
  position 3.5258248313280025 3.676904463515191 1.559909780145742
}
TexturedBackground {
}
TexturedBackgroundLight {
}
Floor {
  size 3 3
}
Solid {
  translation 0 1 0
  children [
    DEF POLE Group {
      children [
        Shape {
          appearance PBRAppearance {
            baseColor 0.652857 0.64683 0.657359
            metalness 0
          }
          geometry Cylinder {
            radius 0.03
          }
        }
        Transform {
          translation 0 1 0
          children [
            Shape {
              appearance PBRAppearance {
                baseColor 0.710491 0.703914 0.715419
                roughness 1
                metalness 0
              }
              geometry Box {
                size 0.5 0.001 0.5
              }
            }
          ]
        }
      ]
    }
  ]
  name "pole"
  contactMaterial "pole"
  boundingObject USE POLE
}
Robot {
  translation 0.001745966367826222 1.723825087623005 -0.00048283932783358633
  rotation -0.20609243410265138 0.3792927128924657 0.9020326748806374 0.017341734230642294
  children [
    Solid {
      children [
        DEF BODY Group {
          children [
            DEF MOTOR_DISPLAY_1 Transform {
              translation -0.086827 0.111023 -0.0296244
              rotation -0.44706108459536525 0.44706208459555447 -0.7747721466066607 1.82325
              children [
                DEF MOTOR_MOCK Shape {
                  appearance PBRAppearance {
                    baseColor 1 0.7 0
                    metalness 0
                  }
                  geometry Cylinder {
                    height 0.02
                    radius 0.008
                  }
                }
              ]
            }
            DEF MOTOR_DISPLAY_2 Transform {
              translation 0.067929 0.11 -0.0623199
              rotation -0.4470590447982244 -0.4470590447982244 0.7747750776375028 1.82325
              children [
                USE MOTOR_MOCK
              ]
            }
            DEF MOTOR_DISPLAY_3 Transform {
              translation 0.02 0.11 0.09
              rotation 0 0 1 -1.5707953071795862
              children [
                USE MOTOR_MOCK
              ]
            }
            DEF PI_BOARD_BAY Transform {
              translation -0.0565695 0.1 -0.101955
              rotation 0 1 0 1.0467
              children [
                DEF PI_BAY Shape {
                  appearance PBRAppearance {
                    baseColor 0.3 0.7 0.3
                    roughness 1
                    metalness 0
                  }
                  geometry Box {
                    size 0.0856 0.011 0.026
                  }
                }
              ]
            }
            DEF MOTOR_BAY_1 Transform {
              translation 0.0529161 0.1 -0.0882933
              rotation 0 1 0 -1.0467
              children [
                DEF MOTOR_BAY Shape {
                  appearance PBRAppearance {
                    baseColor 0.8 0.8 0.9
                    roughness 1
                    metalness 0
                  }
                  geometry Box {
                    size 0.105 0.011 0.034
                  }
                }
              ]
            }
            DEF MOTOR_BAY_2 Transform {
              translation 0.05 0.1 0.09
              children [
                USE MOTOR_BAY
              ]
            }
            DEF MOTOR_BAY_3 Transform {
              translation -0.102959 0.1 -0.00171543
              rotation 0 1 0 1.0467
              children [
                USE MOTOR_BAY
              ]
            }
            DEF SMALL_JOINT_3 Transform {
              translation -0.12985 0.1 0.0750989
              rotation 0 1 0 -1.0467
              children [
                DEF SMALL_BODY_SIDE Shape {
                  appearance PBRAppearance {
                    baseColor 0.2 0.2 0.3
                    metalness 0
                  }
                  geometry Box {
                    size 0.1 0.03 0.01
                  }
                }
              ]
            }
            DEF SMALL_JOINT_2 Transform {
              translation 0.12985 0.1 0.075099
              rotation 0 1 0 1.0467
              children [
                USE SMALL_BODY_SIDE
              ]
            }
            DEF BACK_PLATE_1 Transform {
              translation 0 0.1 0.11
              children [
                DEF BODY_SIDE Shape {
                  appearance PBRAppearance {
                    baseColor 0.2 0.2 0.3
                    roughness 1
                    metalness 0
                  }
                  geometry Box {
                    size 0.221 0.03 0.01
                  }
                }
              ]
            }
            DEF SMALL_JOINT_1 Transform {
              translation 0 0.1 -0.15
              children [
                USE SMALL_BODY_SIDE
              ]
            }
            DEF BACK_PLATE_2 Transform {
              translation -0.0952532 0.1 -0.0550129
              rotation 0 1 0 1.0467
              children [
                DEF TEST Shape {
                  appearance PBRAppearance {
                    baseColor 0.2 0.2 0.3
                    roughness 1
                    metalness 0
                  }
                  geometry Box {
                    size 0.221 0.03 0.01
                  }
                }
              ]
            }
            DEF BACK_PLATE_3 Transform {
              translation 0.0952532 0.1 -0.0550129
              rotation 0 1 0 -1.0467
              children [
                Shape {
                  appearance PBRAppearance {
                    baseColor 0.2 0.2 0.3
                    roughness 1
                    metalness 0
                  }
                  geometry Box {
                    size 0.221 0.03 0.01
                  }
                }
              ]
            }
            Transform {
              translation 0.0175 0.1 0.055
              children [
                DEF BODY_CONNECTOR_SHORT Shape {
                  appearance PBRAppearance {
                    baseColor 0.2 0.2 0.3
                    roughness 1
                    metalness 0
                  }
                  geometry Box {
                    size 0.005 0.01 0.04
                  }
                }
              ]
            }
            Transform {
              translation -0.0175 0.1 0.075
              children [
                DEF BODY_CONNECTOR_LONG Shape {
                  appearance PBRAppearance {
                    baseColor 0.2 0.2 0.3
                    roughness 1
                    metalness 0
                  }
                  geometry Box {
                    size 0.005 0.01 0.079
                  }
                }
              ]
            }
            Transform {
              translation -0.0562046 0.1 -0.052653
              rotation 0 1 0 1.0476
              children [
                USE BODY_CONNECTOR_LONG
              ]
            }
            Transform {
              translation -0.0564 0.1 -0.0123
              rotation 0 1 0 1.0476
              children [
                USE BODY_CONNECTOR_SHORT
              ]
            }
            Transform {
              translation 0.03888 0.1 -0.04266
              rotation 0 1 0 -1.0467
              children [
                USE BODY_CONNECTOR_SHORT
              ]
            }
            Transform {
              translation 0.0737156 0.1 -0.0223086
              rotation 0 1 0 -1.0467
              children [
                USE BODY_CONNECTOR_LONG
              ]
            }
            Transform {
              translation 0 0.1 0.045
              rotation 0 0 1 1.5708
              children [
                DEF AXIS Shape {
                  appearance PBRAppearance {
                    baseColor 0.2 0.2 0.3
                    roughness 1
                    metalness 0
                  }
                  geometry Cylinder {
                    height 0.039
                    radius 0.003
                  }
                }
              ]
            }
            Transform {
              translation -0.03897 0.1 -0.0225
              rotation -0.866019052628739 0 -0.5000110003630134 1.5707999999999998
              children [
                USE AXIS
              ]
            }
            Transform {
              translation 0.03897 0.1 -0.0225
              rotation 0.8660190526287391 0 -0.5000110003630134 1.5708
              children [
                USE AXIS
              ]
            }
          ]
        }
        Group {
          children [
            SolidPipe {
              translation 0 0.13 0
              name "UV module"
              height 0.02
              radius 0.05
              thickness 0.005
              appearance PBRAppearance {
                roughness 1
                metalness 0
              }
              physics Physics {
              }
            }
            Solid {
              translation 0.088 0.12 0.05
              rotation 0.7255771900217981 -0.5459391429762939 -0.4189131097093782 -1.6267153071795866
              children [
                DEF UV_CONNECTOR Shape {
                  appearance PBRAppearance {
                    roughness 1
                    metalness 0
                  }
                  geometry Cylinder {
                    height 0.11
                    radius 0.004
                  }
                }
              ]
            }
            Transform {
              translation 0 0.12 -0.099
              rotation 1 0 0 1.309
              children [
                USE UV_CONNECTOR
              ]
            }
            Transform {
              translation -0.087 0.12 0.05
              rotation 0.7255801029453123 0.5459360774574161 0.41891205943524723 -1.626705307179586
              children [
                USE UV_CONNECTOR
              ]
            }
          ]
        }
      ]
      boundingObject USE BODY
      physics Physics {
      }
    }
    LED {
      translation 0 0.13 0
      children [
        SolidPipe {
          name "leds"
          height 0.01
          radius 0.045
          thickness 0.003
          appearance PBRAppearance {
            baseColor 0.7 0.7 0.7
            roughness 0.3
            metalness 0
            emissiveIntensity 6
          }
        }
      ]
      name "uv_led"
      color [
        0.5 0 1
      ]
      gradual TRUE
    }
    HingeJoint {
      jointParameters HingeJointParameters {
        position 104.15986178057918
        axis -1 0 0
        anchor 0 0.1 0.045
      }
      device [
        RotationalMotor {
          name "wheel1"
        }
      ]
      endPoint Solid {
        translation -3.492307801909843e-08 0.10000190115412273 0.04499878545876559
        rotation 0.7011304066161924 -0.7011326123919777 0.12972745568542385 2.8835795783439497
        children [
          DEF WHEEL_CENTRE Shape {
            appearance PBRAppearance {
              metalness 0
            }
            geometry Cylinder {
              height 0.021
              radius 0.012
            }
          }
          DEF WHEEL Shape {
            appearance PBRAppearance {
              baseColor 0 0 0
              roughness 1
              metalness 0
            }
            geometry Cylinder {
              height 0.02
              radius 0.016
            }
          }
        ]
        name "wheel_shape1"
        contactMaterial "wheel"
        boundingObject USE WHEEL
        physics DEF WHEEL_PH Physics {
        }
        linearVelocity 0.0011780597416852054 -0.07602143643107027 0.00025792361486803134
        angularVelocity 4.947571528021642 0.07799122078931146 -0.04118789280311759
      }
    }
    HingeJoint {
      jointParameters HingeJointParameters {
        position 104.15979202532647
        axis 0.5 0 0.866
        anchor 0.039 0.1 -0.0225
      }
      device [
        RotationalMotor {
          name "wheel2"
        }
      ]
      endPoint Solid {
        translation 0.03899873596305173 0.10000128657151146 -0.022499356427054692
        rotation -0.23824713690637517 -0.7011352530891437 -0.6720473633841125 2.883629312794296
        children [
          USE WHEEL_CENTRE
          USE WHEEL
        ]
        name "wheel_shape2"
        contactMaterial "wheel"
        boundingObject USE WHEEL
        physics USE WHEEL_PH
        linearVelocity 0.001257462105571708 -0.07983445568035645 0.0002683910960542546
        angularVelocity -2.580387061645423 -0.05261240745510456 -4.321207741051761
      }
    }
    HingeJoint {
      jointParameters HingeJointParameters {
        position 104.15972570080409
        axis 0.5 0 -0.866
        anchor -0.039 0.1 -0.0225
      }
      device [
        RotationalMotor {
          name "wheel3"
        }
      ]
      endPoint Solid {
        translation -0.03899846676468961 0.10000115727067065 -0.022499173390146735
        rotation -0.4628790375683028 -0.7011371802510816 0.5423556499654119 2.8836718342416576
        children [
          USE WHEEL_CENTRE
          USE WHEEL
        ]
        name "wheel_shape3"
        contactMaterial "wheel"
        boundingObject USE WHEEL
        physics USE WHEEL_PH
        linearVelocity 0.0012315723908602767 -0.07917645911984861 0.0002441476505849561
        angularVelocity -2.5235760689848825 -0.02861436989990365 4.3380748760841366
      }
    }
    DistanceSensor {
      translation 0 0.115 0.11
      rotation 0 0 1 1.5708
      children [
        DEF D_SENSOR Shape {
          appearance PBRAppearance {
            baseColor 1 0 0
            roughness 1
            metalness 0
          }
          geometry Box {
            size 0.005 0.01 0.005
          }
        }
      ]
      name "ds_top"
      boundingObject USE D_SENSOR
      physics Physics {
      }
      translationStep 0.1
      rotationStep 0.4
      numberOfRays 4
      aperture 2
      gaussianWidth 7
    }
    DistanceSensor {
      translation 0 0.085 0.105
      rotation 0 0 1 -1.5708
      children [
        USE D_SENSOR
      ]
      name "ds_bottom"
      boundingObject USE D_SENSOR
      physics Physics {
      }
      translationStep 0.1
      rotationStep 0.4
      numberOfRays 4
      aperture 2
      gaussianWidth 7
    }
  ]
  name "PAUL"
  boundingObject USE BODY
  physics Physics {
  }
  rotationStep 0.1
  controller "PAUL_withLED"
  linearVelocity 0.0012366878278327583 -0.07859295003285599 0.00019599847065143874
  angularVelocity -0.05169411074124568 -0.0010680289853289527 -0.008079937012807285
}
